I'm sorry, but an uncaught exception occurred.

While running game code:
  File "game/script.rpy", line 59, in script call
    call show_dialogue("elodia")
  File "game/script.rpy", line 85, in script
    $ desired_drink = desired_drinks["elodia"]
  File "game/script.rpy", line 85, in <module>
    $ desired_drink = desired_drinks["elodia"]
KeyError: 'elodia'

-- Full Traceback ------------------------------------------------------------

Full traceback:
  File "game/script.rpy", line 59, in script call
    call show_dialogue("elodia")
  File "game/script.rpy", line 85, in script
    $ desired_drink = desired_drinks["elodia"]
  File "C:\Users\Leonela\Downloads\renpy-8.3.2-sdk\renpy\ast.py", line 821, in execute
    renpy.python.py_exec_bytecode(self.code.bytecode, self.hide, store=self.store)
  File "C:\Users\Leonela\Downloads\renpy-8.3.2-sdk\renpy\python.py", line 1178, in py_exec_bytecode
    exec(bytecode, globals, locals)
  File "game/script.rpy", line 85, in <module>
    $ desired_drink = desired_drinks["elodia"]
KeyError: 'elodia'

Windows-10-10.0.19045 AMD64
Ren'Py 8.3.2.24090902
Celler_de_mites 1.0
Wed Oct 30 06:50:42 2024
